I'm sorry, but an uncaught exception occurred.

While running game code:
  File "game/script.rpy", line 30, in script call
    call s1p1
  File "game/script.rpy", line 109, in script
    a "Well, I hope to meet with some old acquaintances and eat some good dinner here soon, the munchies are killing me!"
Exception: Sayer 'a' is not defined.

-- Full Traceback ------------------------------------------------------------

Full traceback:
  File "game/script.rpy", line 30, in script call
    call s1p1
  File "game/script.rpy", line 109, in script
    a "Well, I hope to meet with some old acquaintances and eat some good dinner here soon, the munchies are killing me!"
  File "D:\Renpy\renpy-8.3.0-sdk\renpy\ast.py", line 2572, in execute
    Say.execute(self)
  File "D:\Renpy\renpy-8.3.0-sdk\renpy\ast.py", line 575, in execute
    who = eval_who(self.who, self.who_fast)
  File "D:\Renpy\renpy-8.3.0-sdk\renpy\ast.py", line 464, in eval_who
    raise Exception("Sayer '%s' is not defined." % who)
Exception: Sayer 'a' is not defined.

Windows-10-10.0.22631 AMD64
Ren'Py 8.3.0.24082114
RaveWeen 1.0
Sat Sep  7 02:17:56 2024
